Workbook

Sheet Table
E3: Classification Threshold | F3: Visually-Verified Events | P3: All Events (Visually-Verified & Acoustic Only)
F4: Dataset | G4: Predicted | H4: TP | I4: FP | J4: TN | K4: FN | L4: FPR | M4: FNR | N4: Precision | O4: Recall | P4: Predicted | Q4: TP | R4: FP | S4: TN | T4: FN | U4: FPR | V4: FNR | W4: Precision | X4: Recall
E5: 0.5 | F5: Baseline | G5: 40 | H5: 31 | I5: 9 | J5: =121+90+8 -> 219 | K5: 0 | L5: 0.039473684 | M5: 0 | N5: 0.775 | O5: 1 | P5: 133 | Q5: 57 | R5: 74 | S5: 931 | T5: 0 | U5: 0.073631841 | V5: 0 | W5: 0.4351145 | X5: 1
E6: 0.5 | F6: Filtered | G6: 31 | H6: 31 | I6: 0 | J6: =121+90+8 -> 219 | K6: 0 | L6: 0 | M6: 0 | N6: 1 | O6: 1 | P6: 57 | Q6: 57 | R6: 0 | S6: 931 | T6: 0 | U6: 0 | V6: 0 | W6: 1 | X6: 1
E7: 0.6 | F7: Baseline | G7: 32 | H7: 30 | I7: 2 | J7: =121+90+8 -> 219 | K7: 1 | L7: 0.0090497738 | M7: 0.032258065 | N7: 0.9375 | O7: 0.96774194 | P7: 95 | Q7: 52 | R7: 41 | S7: 931 | T7: 5 | U7: 0.04218107 | V7: 0.087719298 | W7: 0.55913978 | X7: 0.9122807
E8: 0.6 | F8: Filtered | G8: 30 | H8: 30 | I8: 0 | J8: =121+90+8 -> 219 | K8: 1 | L8: 0 | M8: 0.032258065 | N8: 1 | O8: 0.96774194 | P8: 52 | Q8: 52 | R8: 0 | S8: 931 | T8: 5 | U8: 0 | V8: 0.087719298 | W8: 1 | X8: 0.9122807
E9: 0.7 | F9: Baseline | G9: 31 | H9: 29 | I9: 2 | J9: =121+90+8 -> 219 | K9: 2 | L9: 0.0090497738 | M9: 0.064516129 | N9: 0.93548387 | O9: 0.93548387 | P9: 69 | Q9: 45 | R9: 22 | S9: 931 | T9: 12 | U9: 0.023084995 | V9: 0.21052632 | W9: 0.67164179 | X9: 0.78947368
E10: 0.7 | F10: Filtered | G10: 29 | H10: 29 | I10: 0 | J10: =121+90+8 -> 219 | K10: 2 | L10: 0 | M10: 0.064516129 | N10: 1 | O10: 0.93548387 | P10: 45 | Q10: 45 | R10: 0 | S10: 931 | T10: 12 | U10: 0 | V10: 0.21052632 | W10: 1 | X10: 0.78947368
E11: 0.8 | F11: Baseline | G11: 23 | H11: 23 | I11: 0 | J11: =121+90+8 -> 219 | K11: 8 | L11: 0 | M11: 0.25806452 | N11: 1 | O11: 0.74193548 | P11: 39 | Q11: 35 | R11: 4 | S11: 931 | T11: 22 | U11: 0.0042780749 | V11: 0.38596491 | W11: 0.8974359 | X11: 0.61403509
E12: 0.8 | F12: Filtered | G12: 23 | H12: 23 | I12: 0 | J12: =121+90+8 -> 219 | K12: 8 | L12: 0 | M12: 0.25806452 | N12: 1 | O12: 0.74193548 | P12: 35 | Q12: 35 | R12: 0 | S12: 931 | T12: 22 | U12: 0 | V12: 0.38596491 | W12: 1 | X12: 0.61403509
E13: 0.9 | F13: Baseline | G13: 10 | H13: 10 | I13: 0 | J13: =121+90+8 -> 219 | K13: 21 | L13: 0 | M13: 0.67741935 | N13: 1 | O13: 0.32258065 | P13: 12 | Q13: 12 | R13: 0 | S13: 931 | T13: 45 | U13: 0 | V13: 0.78947368 | W13: 1 | X13: 0.21052632
E14: 0.9 | F14: Filtered | G14: 10 | H14: 10 | I14: 0 | J14: =121+90+8 -> 219 | K14: 21 | L14: 0 | M14: 0.67741935 | N14: 1 | O14: 0.32258065 | P14: 12 | Q14: 12 | R14: 0 | S14: 931 | T14: 45 | U14: 0 | V14: 0.78947368 | W14: 1 | X14: 0.21052632
H17: Total VV Predicted (TP+FP+TN+FN) | R17: Total VVAO Predicted (TP+FP+TN+FN)
H18: =SUM(G22:K22) -> 299 | R18: =SUM(Q22:T22) -> 1067
E20: Classification Threshold | F20: Visually-Verified Events | P20: All Events (Visually-Verified & Acoustic Only)
C21: Predicted VV | D21: Predicted All | F21: Dataset | G21: Predicted as Pc | H21: TP | I21: FP | J21: TN | K21: FN | L21: FPR | M21: FNR | N21: Precision | O21: Recall | P21: Predicted as Pc | Q21: TP | R21: FP | S21: TN | T21: FN | U21: FPR | V21: FNR | W21: Precision | X21: Recall
C22: =H22+I22 -> 40 | D22: =Q22+R22 -> 133 | E22: 0.5 | F22: Baseline | G22: 40 | H22: 31 | I22: 9 | J22: =121+90+8 -> 219 | K22: 0 | L22: 0.039473684 | M22: 0 | N22: 0.775 | O22: 1 | P22: 133 | Q22: 58 | R22: 75 | S22: 933 | T22: 1 | U22: =R22/(R22+S22) -> 0.074404762 | V22: =T22/(T22+Q22) -> 0.016949153 | W22: =Q22/(Q22+R22) -> 0.43609023 | X22: =Q22/(Q22+T22) -> 0.98305085 | Y22: =SUM(Q22:T22) -> 1067
C23: =H23+I23 -> 32 | D23: =Q23+R23 -> 95 | E23: 0.6 | F23: Baseline | G23: 32 | H23: 30 | I23: 2 | J23: =121+90+8 -> 219 | K23: 1 | L23: 0.0090497738 | M23: 0.032258065 | N23: 0.9375 | O23: 0.96774194 | P23: 95 | Q23: 53 | R23: 42 | S23: 933 | T23: 6 | U23: =R23/(R23+S23) -> 0.043076923 | V23: =T23/(T23+Q23) -> 0.10169492 | W23: =Q23/(Q23+R23) -> 0.55789474 | X23: =Q23/(Q23+T23) -> 0.89830508 | Y23: =SUM(Q23:T23) -> 1034
C24: =H24+I24 -> 31 | D24: =Q24+R24 -> 69 | E24: 0.7 | F24: Baseline | G24: 31 | H24: 29 | I24: 2 | J24: =121+90+8 -> 219 | K24: 2 | L24: 0.0090497738 | M24: 0.064516129 | N24: 0.93548387 | O24: 0.93548387 | P24: 69 | Q24: 45 | R24: 24 | S24: 933 | T24: 13 | U24: =R24/(R24+S24) -> 0.02507837 | V24: =T24/(T24+Q24) -> 0.22413793 | W24: =Q24/(Q24+R24) -> 0.65217391 | X24: =Q24/(Q24+T24) -> 0.77586207
C25: =H25+I25 -> 23 | D25: =Q25+R25 -> 39 | E25: 0.8 | F25: Baseline | G25: 23 | H25: 23 | I25: 0 | J25: =121+90+8 -> 219 | K25: 8 | L25: 0 | M25: 0.25806452 | N25: 1 | O25: 0.74193548 | P25: 39 | Q25: 35 | R25: 4 | S25: 933 | T25: 23 | U25: =R25/(R25+S25) -> 0.0042689434 | V25: =T25/(T25+Q25) -> 0.39655172 | W25: =Q25/(Q25+R25) -> 0.8974359 | X25: =Q25/(Q25+T25) -> 0.60344828
C26: =H26+I26 -> 10 | D26: =Q26+R26 -> 12 | E26: 0.9 | F26: Baseline | G26: 10 | H26: 10 | I26: 0 | J26: =121+90+8 -> 219 | K26: 21 | L26: 0 | M26: 0.67741935 | N26: 1 | O26: 0.32258065 | P26: 12 | Q26: 12 | R26: 0 | S26: 933 | T26: 46 | U26: =R26/(R26+S26) -> 0 | V26: =T26/(T26+Q26) -> 0.79310345 | W26: =Q26/(Q26+R26) -> 1 | X26: =Q26/(Q26+T26) -> 0.20689655
C27: =H27+I27 -> 31 | D27: =Q27+R27 -> 57 | E27: 0.5 | F27: Filtered | G27: 31 | H27: 31 | I27: 0 | J27: =121+90+8 -> 219 | K27: 0 | L27: 0 | M27: 0 | N27: 1 | O27: 1 | P27: 57 | Q27: 57 | R27: 0 | S27: 931 | T27: 0 | U27: =R27/(R27+S27) -> 0 | V27: =T27/(T27+Q27) -> 0 | W27: =Q27/(Q27+R27) -> 1 | X27: =Q27/(Q27+T27) -> 1
C28: =H28+I28 -> 30 | D28: =Q28+R28 -> 52 | E28: 0.6 | F28: Filtered | G28: 30 | H28: 30 | I28: 0 | J28: =121+90+8 -> 219 | K28: 1 | L28: 0 | M28: 0.032258065 | N28: 1 | O28: 0.96774194 | P28: 52 | Q28: 52 | R28: 0 | S28: 931 | T28: 5 | U28: =R28/(R28+S28) -> 0 | V28: =T28/(T28+Q28) -> 0.087719298 | W28: =Q28/(Q28+R28) -> 1 | X28: =Q28/(Q28+T28) -> 0.9122807
C29: =H29+I29 -> 29 | D29: =Q29+R29 -> 45 | E29: 0.7 | F29: Filtered | G29: 29 | H29: 29 | I29: 0 | J29: =121+90+8 -> 219 | K29: 2 | L29: 0 | M29: 0.064516129 | N29: 1 | O29: 0.93548387 | P29: 45 | Q29: 45 | R29: 0 | S29: 931 | T29: 12 | U29: =R29/(R29+S29) -> 0 | V29: =T29/(T29+Q29) -> 0.21052632 | W29: =Q29/(Q29+R29) -> 1 | X29: =Q29/(Q29+T29) -> 0.78947368
C30: =H30+I30 -> 23 | D30: =Q30+R30 -> 35 | E30: 0.8 | F30: Filtered | G30: 23 | H30: 23 | I30: 0 | J30: =121+90+8 -> 219 | K30: 8 | L30: 0 | M30: 0.25806452 | N30: 1 | O30: 0.74193548 | P30: 35 | Q30: 35 | R30: 0 | S30: 931 | T30: 22 | U30: =R30/(R30+S30) -> 0 | V30: =T30/(T30+Q30) -> 0.38596491 | W30: =Q30/(Q30+R30) -> 1 | X30: =Q30/(Q30+T30) -> 0.61403509
C31: =H31+I31 -> 10 | D31: =Q31+R31 -> 12 | E31: 0.9 | F31: Filtered | G31: 10 | H31: 10 | I31: 0 | J31: =121+90+8 -> 219 | K31: 21 | L31: 0 | M31: 0.67741935 | N31: 1 | O31: 0.32258065 | P31: 12 | Q31: 12 | R31: 0 | S31: 931 | T31: 45 | U31: =R31/(R31+S31) -> 0 | V31: =T31/(T31+Q31) -> 0.78947368 | W31: =Q31/(Q31+R31) -> 1 | X31: =Q31/(Q31+T31) -> 0.21052632

Sheet Totals_long
A1: trial | B1: data_type | C1: class_thld | D1: pred_pc | E1: tp | F1: fp | G1: tn | H1: fn | I1: fpr | J1: fpr_vis | K1: fnr | L1: precision | M1: recall | N1: specificity | O1: bal_accuracy
A2: baseline | B2: all | C2: 0.5 | D2: =SCOPE!B11+HICEAS17!B11+HICEAS23!B11 -> 133 | E2: =SCOPE!C11+HICEAS17!C11+HICEAS23!C11 -> 57 | F2: =SCOPE!D11+HICEAS17!D11+HICEAS23!D11 -> 74 | G2: =108+486+337 -> 931 | H2: =SCOPE!E11+HICEAS17!E11+HICEAS23!E11 -> 0 | I2: =F2/(F2+G2) -> 0.073631841 | K2: =H2/(E2+H2) -> 0 | L2: =E2/(E2+F2) -> 0.4351145 | M2: =E2/(E2+H2) -> 1 | N2: =108/(108+F2) -> 0.59340659 | O2: =(M2+N2)/2 -> 0.7967033
A3: filtered | B3: all | C3: 0.5 | D3: 57 | E3: 57 | F3: 0 | G3: =108+486+337 -> 931 | H3: 0 | I3: =F3/(F3+G3) -> 0 | K3: 0 | L3: 1 | M3: 1 | N3: 1 | O3: 1
A4: baseline | B4: all | C4: 0.6 | D4: =SCOPE!B12+HICEAS17!B12+HICEAS23!B12 -> 95 | E4: =SCOPE!C12+HICEAS17!C12+HICEAS23!C12 -> 52 | F4: =SCOPE!D12+HICEAS17!D12+HICEAS23!D12 -> 41 | G4: =108+486+337 -> 931 | H4: =SCOPE!E12+HICEAS17!E12+HICEAS23!E12 -> 5 | I4: =F4/(F4+G4) -> 0.04218107 | K4: =H4/(E4+H4) -> 0.087719298 | L4: =E4/(E4+F4) -> 0.55913978 | M4: =E4/(E4+H4) -> 0.9122807 | N4: =108/(108+F4) -> 0.72483221 | O4: =(M4+N4)/2 -> 0.81855646
A5: filtered | B5: all | C5: 0.6 | D5: 52 | E5: 52 | F5: 0 | G5: =108+486+337 -> 931 | H5: 5 | I5: =F5/(F5+G5) -> 0 | K5: 0.087719298 | L5: 1 | M5: 0.9122807 | N5: 1 | O5: 0.95614035
A6: baseline | B6: all | C6: 0.7 | D6: =SCOPE!B13+HICEAS17!B13+HICEAS23!B13 -> 69 | E6: =SCOPE!C13+HICEAS17!C13+HICEAS23!C13 -> 45 | F6: =SCOPE!D13+HICEAS17!D13+HICEAS23!D13 -> 22 | G6: =108+486+337 -> 931 | H6: =SCOPE!E13+HICEAS17!E13+HICEAS23!E13 -> 12 | I6: =F6/(F6+G6) -> 0.023084995 | K6: =H6/(E6+H6) -> 0.21052632 | L6: =E6/(E6+F6) -> 0.67164179 | M6: =E6/(E6+H6) -> 0.78947368 | N6: =108/(108+F6) -> 0.83076923 | O6: =(M6+N6)/2 -> 0.81012146
A7: filtered | B7: all | C7: 0.7 | D7: 45 | E7: 45 | F7: 0 | G7: =108+486+337 -> 931 | H7: 12 | I7: =F7/(F7+G7) -> 0 | K7: 0.21052632 | L7: 1 | M7: 0.78947368 | N7: 1 | O7: 0.89473684
A8: baseline | B8: all | C8: 0.8 | D8: =SCOPE!B14+HICEAS17!B14+HICEAS23!B14 -> 39 | E8: =SCOPE!C14+HICEAS17!C14+HICEAS23!C14 -> 35 | F8: =SCOPE!D14+HICEAS17!D14+HICEAS23!D14 -> 4 | G8: =108+486+337 -> 931 | H8: =SCOPE!E14+HICEAS17!E14+HICEAS23!E14 -> 22 | I8: =F8/(F8+G8) -> 0.0042780749 | K8: =H8/(E8+H8) -> 0.38596491 | L8: =E8/(E8+F8) -> 0.8974359 | M8: =E8/(E8+H8) -> 0.61403509 | N8: =108/(108+F8) -> 0.96428571 | O8: =(M8+N8)/2 -> 0.7891604
A9: filtered | B9: all | C9: 0.8 | D9: 35 | E9: 35 | F9: 0 | G9: =108+486+337 -> 931 | H9: 22 | I9: =F9/(F9+G9) -> 0 | K9: 0.38596491 | L9: 1 | M9: 0.61403509 | N9: 1 | O9: 0.80701754
A10: baseline | B10: all | C10: 0.9 | D10: =SCOPE!B15+HICEAS17!B15+HICEAS23!B15 -> 12 | E10: =SCOPE!C15+HICEAS17!C15+HICEAS23!C15 -> 12 | F10: =SCOPE!D15+HICEAS17!D15+HICEAS23!D15 -> 0 | G10: =108+486+337 -> 931 | H10: =SCOPE!E15+HICEAS17!E15+HICEAS23!E15 -> 45 | I10: =F10/(F10+G10) -> 0 | K10: =H10/(E10+H10) -> 0.78947368 | L10: =E10/(E10+F10) -> 1 | M10: =E10/(E10+H10) -> 0.21052632 | N10: =108/(108+F10) -> 1 | O10: =(M10+N10)/2 -> 0.60526316
A11: filtered | B11: all | C11: 0.9 | D11: 12 | E11: 12 | F11: 0 | G11: =108+486+337 -> 931 | H11: 45 | I11: =F11/(F11+G11) -> 0 | K11: 0.78947368 | L11: 1 | M11: 0.21052632 | N11: 1 | O11: 0.60526316
A12: baseline | B12: visual | C12: 0.5 | D12: =SCOPE!B3+HICEAS17!B3+HICEAS23!B3 -> 40 | E12: =SCOPE!C3+HICEAS17!C3+HICEAS23!C3 -> 31 | F12: =SCOPE!D3+HICEAS17!D3+HICEAS23!D3 -> 9 | H12: =SCOPE!E3+HICEAS17!E3+HICEAS23!E3 -> 0 | I12: =$F12/($F12+108+486+337) -> 0.0095744681 | J12: =$F12/($F12+Table!J5) -> 0.039473684 | K12: =H12/(E12+H12) -> 0 | L12: =E12/(E12+F12) -> 0.775 | M12: =E12/(E12+H12) -> 1 | N12: =108/(108+F12) -> 0.92307692 | O12: =(M12+N12)/2 -> 0.96153846
A13: filtered | B13: visual | C13: 0.5 | D13: 31 | E13: 31 | F13: 0 | H13: 0 | I13: 0 | J13: =$F13/($F13+Table!J6) -> 0 | K13: 0 | L13: 1 | M13: 1 | N13: 1 | O13: 1
A14: baseline | B14: visual | C14: 0.6 | D14: =SCOPE!B4+HICEAS17!B4+HICEAS23!B4 -> 32 | E14: =SCOPE!C4+HICEAS17!C4+HICEAS23!C4 -> 30 | F14: =SCOPE!D4+HICEAS17!D4+HICEAS23!D4 -> 2 | H14: =SCOPE!E4+HICEAS17!E4+HICEAS23!E4 -> 1 | I14: =F14/(F14+108+486+337) -> 0.0021436227 | J14: =$F14/($F14+Table!J7) -> 0.0090497738 | K14: =H14/(E14+H14) -> 0.032258065 | L14: =E14/(E14+F14) -> 0.9375 | M14: =E14/(E14+H14) -> 0.96774194 | N14: =108/(108+F14) -> 0.98181818 | O14: =(M14+N14)/2 -> 0.97478006
A15: filtered | B15: visual | C15: 0.6 | D15: 30 | E15: 30 | F15: 0 | H15: 1 | I15: 0 | J15: =$F15/($F15+Table!J8) -> 0 | K15: 0.032258065 | L15: 1 | M15: 0.96774194 | N15: 1 | O15: 0.98387097
A16: baseline | B16: visual | C16: 0.7 | D16: =SCOPE!B5+HICEAS17!B5+HICEAS23!B5 -> 31 | E16: =SCOPE!C5+HICEAS17!C5+HICEAS23!C5 -> 29 | F16: =SCOPE!D5+HICEAS17!D5+HICEAS23!D5 -> 2 | H16: =SCOPE!E5+HICEAS17!E5+HICEAS23!E5 -> 2 | I16: =F16/(F16+108+486+337) -> 0.0021436227 | J16: =$F16/($F16+Table!J9) -> 0.0090497738 | K16: =H16/(E16+H16) -> 0.064516129 | L16: =E16/(E16+F16) -> 0.93548387 | M16: =E16/(E16+H16) -> 0.93548387 | N16: =108/(108+F16) -> 0.98181818 | O16: =(M16+N16)/2 -> 0.95865103
A17: filtered | B17: visual | C17: 0.7 | D17: 29 | E17: 29 | F17: 0 | H17: 2 | I17: 0 | J17: =$F17/($F17+Table!J10) -> 0 | K17: 0.064516129 | L17: 1 | M17: 0.93548387 | N17: 1 | O17: 0.96774194
A18: baseline | B18: visual | C18: 0.8 | D18: =SCOPE!B6+HICEAS17!B6+HICEAS23!B6 -> 23 | E18: =SCOPE!C6+HICEAS17!C6+HICEAS23!C6 -> 23 | F18: =SCOPE!D6+HICEAS17!D6+HICEAS23!D6 -> 0 | H18: =SCOPE!E6+HICEAS17!E6+HICEAS23!E6 -> 8 | I18: =F18/(F18+108+486+337) -> 0 | J18: =$F18/($F18+Table!J11) -> 0 | K18: =H18/(E18+H18) -> 0.25806452 | L18: =E18/(E18+F18) -> 1 | M18: =E18/(E18+H18) -> 0.74193548 | N18: =108/(108+F18) -> 1 | O18: =(M18+N18)/2 -> 0.87096774
A19: filtered | B19: visual | C19: 0.8 | D19: 23 | E19: 23 | F19: 0 | H19: 8 | I19: 0 | J19: =$F19/($F19+Table!J12) -> 0 | K19: 0.25806452 | L19: 1 | M19: 0.74193548 | N19: 1 | O19: 0.87096774
A20: baseline | B20: visual | C20: 0.9 | D20: =SCOPE!B7+HICEAS17!B7+HICEAS23!B7 -> 10 | E20: =SCOPE!C7+HICEAS17!C7+HICEAS23!C7 -> 10 | F20: =SCOPE!D7+HICEAS17!D7+HICEAS23!D7 -> 0 | H20: =SCOPE!E7+HICEAS17!E7+HICEAS23!E7 -> 21 | I20: =F20/(F20+108+486+337) -> 0 | J20: =$F20/($F20+Table!J13) -> 0 | K20: =H20/(E20+H20) -> 0.67741935 | L20: =E20/(E20+F20) -> 1 | M20: =E20/(E20+H20) -> 0.32258065 | N20: =108/(108+F20) -> 1 | O20: =(M20+N20)/2 -> 0.66129032
A21: filtered | B21: visual | C21: 0.9 | D21: 10 | E21: 10 | F21: 0 | H21: 21 | I21: 0 | J21: =$F21/($F21+Table!J14) -> 0 | K21: 0.67741935 | L21: 1 | M21: 0.32258065 | N21: 1 | O21: 0.66129032

Sheet Totals_wide
A1: Visuals only | M1: MDF + SSF
B2: Predicted Pcs | C2: True positive | D2: false positives | E2: true negatives | F2: false negatives | G2: false positive rate | H2: false negative rate | I2: precision | J2: recall | K2: specificity | L2: balanced accuracy | M2: Predicted Pcs | N2: Correct Pcs | O2: false positives | P2: true negatives | Q2: false negatives | R2: false positive rate | S2: false negative rate | T2: precision | U2: recall | V2: specificity | W2: balanced accuracy
A3: 0.5 | B3: =[1]SCOPE!B3+[1]HICEAS17!B3+[1]HICEAS23!B3 -> 40 | C3: =[1]SCOPE!C3+[1]HICEAS17!C3+[1]HICEAS23!C3 -> 31 | D3: =[1]SCOPE!D3+[1]HICEAS17!D3+[1]HICEAS23!D3 -> 9 | E3: 219 | F3: =[1]SCOPE!E3+[1]HICEAS17!E3+[1]HICEAS23!E3 -> 0 | G3: =D3/(D3+E3) -> 0.039473684 | H3: =F3/(C3+F3) -> 0 | I3: =C3/(C3+D3) -> 0.775 | J3: =C3/(C3+F3) -> 1 | K3: =108/(108+D3) -> 0.92307692 | L3: =(J3+K3)/2 -> 0.96153846 | M3: =[1]SCOPE!L3+[1]HICEAS17!L3+[1]HICEAS23!L3 -> 31 | N3: =[1]SCOPE!M3+[1]HICEAS17!M3+[1]HICEAS23!M3 -> 31 | O3: =[1]SCOPE!N3+[1]HICEAS17!N3+[1]HICEAS23!N3 -> 0 | P3: 219 | Q3: =[1]SCOPE!O3+[1]HICEAS17!O3+[1]HICEAS23!O3 -> 0 | R3: =O3/(O3+P3) -> 0 | S3: =Q3/(N3+Q3) -> 0 | T3: =N3/(N3+O3) -> 1 | U3: =N3/(N3+Q3) -> 1 | V3: =108/(108+O3) -> 1 | W3: =(U3+V3)/2 -> 1
A4: 0.6 | B4: =[1]SCOPE!B4+[1]HICEAS17!B4+[1]HICEAS23!B4 -> 32 | C4: =[1]SCOPE!C4+[1]HICEAS17!C4+[1]HICEAS23!C4 -> 30 | D4: =[1]SCOPE!D4+[1]HICEAS17!D4+[1]HICEAS23!D4 -> 2 | E4: 219 | F4: =[1]SCOPE!E4+[1]HICEAS17!E4+[1]HICEAS23!E4 -> 1 | G4: =D4/(D4+E4) -> 0.0090497738 | H4: =F4/(C4+F4) -> 0.032258065 | I4: =C4/(C4+D4) -> 0.9375 | J4: =C4/(C4+F4) -> 0.96774194 | K4: =108/(108+D4) -> 0.98181818 | L4: =(J4+K4)/2 -> 0.97478006 | M4: =[1]SCOPE!L4+[1]HICEAS17!L4+[1]HICEAS23!L4 -> 30 | N4: =[1]SCOPE!M4+[1]HICEAS17!M4+[1]HICEAS23!M4 -> 30 | O4: =[1]SCOPE!N4+[1]HICEAS17!N4+[1]HICEAS23!N4 -> 0 | P4: 219 | Q4: =[1]SCOPE!O4+[1]HICEAS17!O4+[1]HICEAS23!O4 -> 1 | R4: =O4/(O4+P4) -> 0 | S4: =Q4/(N4+Q4) -> 0.032258065 | T4: =N4/(N4+O4) -> 1 | U4: =N4/(N4+Q4) -> 0.96774194 | V4: =108/(108+O4) -> 1 | W4: =(U4+V4)/2 -> 0.98387097
A5: 0.7 | B5: =[1]SCOPE!B5+[1]HICEAS17!B5+[1]HICEAS23!B5 -> 31 | C5: =[1]SCOPE!C5+[1]HICEAS17!C5+[1]HICEAS23!C5 -> 29 | D5: =[1]SCOPE!D5+[1]HICEAS17!D5+[1]HICEAS23!D5 -> 2 | E5: 219 | F5: =[1]SCOPE!E5+[1]HICEAS17!E5+[1]HICEAS23!E5 -> 2 | G5: =D5/(D5+E5) -> 0.0090497738 | H5: =F5/(C5+F5) -> 0.064516129 | I5: =C5/(C5+D5) -> 0.93548387 | J5: =C5/(C5+F5) -> 0.93548387 | K5: =108/(108+D5) -> 0.98181818 | L5: =(J5+K5)/2 -> 0.95865103 | M5: =[1]SCOPE!L5+[1]HICEAS17!L5+[1]HICEAS23!L5 -> 29 | N5: =[1]SCOPE!M5+[1]HICEAS17!M5+[1]HICEAS23!M5 -> 29 | O5: =[1]SCOPE!N5+[1]HICEAS17!N5+[1]HICEAS23!N5 -> 0 | P5: 219 | Q5: =[1]SCOPE!O5+[1]HICEAS17!O5+[1]HICEAS23!O5 -> 2 | R5: =O5/(O5+P5) -> 0 | S5: =Q5/(N5+Q5) -> 0.064516129 | T5: =N5/(N5+O5) -> 1 | U5: =N5/(N5+Q5) -> 0.93548387 | V5: =108/(108+O5) -> 1 | W5: =(U5+V5)/2 -> 0.96774194
A6: 0.8 | B6: =[1]SCOPE!B6+[1]HICEAS17!B6+[1]HICEAS23!B6 -> 23 | C6: =[1]SCOPE!C6+[1]HICEAS17!C6+[1]HICEAS23!C6 -> 23 | D6: =[1]SCOPE!D6+[1]HICEAS17!D6+[1]HICEAS23!D6 -> 0 | E6: 219 | F6: =[1]SCOPE!E6+[1]HICEAS17!E6+[1]HICEAS23!E6 -> 8 | G6: =D6/(D6+E6) -> 0 | H6: =F6/(C6+F6) -> 0.25806452 | I6: =C6/(C6+D6) -> 1 | J6: =C6/(C6+F6) -> 0.74193548 | K6: =108/(108+D6) -> 1 | L6: =(J6+K6)/2 -> 0.87096774 | M6: =[1]SCOPE!L6+[1]HICEAS17!L6+[1]HICEAS23!L6 -> 23 | N6: =[1]SCOPE!M6+[1]HICEAS17!M6+[1]HICEAS23!M6 -> 23 | O6: =[1]SCOPE!N6+[1]HICEAS17!N6+[1]HICEAS23!N6 -> 0 | P6: 219 | Q6: =[1]SCOPE!O6+[1]HICEAS17!O6+[1]HICEAS23!O6 -> 8 | R6: =O6/(O6+P6) -> 0 | S6: =Q6/(N6+Q6) -> 0.25806452 | T6: =N6/(N6+O6) -> 1 | U6: =N6/(N6+Q6) -> 0.74193548 | V6: =108/(108+O6) -> 1 | W6: =(U6+V6)/2 -> 0.87096774
A7: 0.9 | B7: =[1]SCOPE!B7+[1]HICEAS17!B7+[1]HICEAS23!B7 -> 10 | C7: =[1]SCOPE!C7+[1]HICEAS17!C7+[1]HICEAS23!C7 -> 10 | D7: =[1]SCOPE!D7+[1]HICEAS17!D7+[1]HICEAS23!D7 -> 0 | E7: 219 | F7: =[1]SCOPE!E7+[1]HICEAS17!E7+[1]HICEAS23!E7 -> 21 | G7: =D7/(D7+E7) -> 0 | H7: =F7/(C7+F7) -> 0.67741935 | I7: =C7/(C7+D7) -> 1 | J7: =C7/(C7+F7) -> 0.32258065 | K7: =108/(108+D7) -> 1 | L7: =(J7+K7)/2 -> 0.66129032 | M7: =[1]SCOPE!L7+[1]HICEAS17!L7+[1]HICEAS23!L7 -> 10 | N7: =[1]SCOPE!M7+[1]HICEAS17!M7+[1]HICEAS23!M7 -> 10 | O7: =[1]SCOPE!N7+[1]HICEAS17!N7+[1]HICEAS23!N7 -> 0 | P7: 219 | Q7: =[1]SCOPE!O7+[1]HICEAS17!O7+[1]HICEAS23!O7 -> 21 | R7: =O7/(O7+P7) -> 0 | S7: =Q7/(N7+Q7) -> 0.67741935 | T7: =N7/(N7+O7) -> 1 | U7: =N7/(N7+Q7) -> 0.32258065 | V7: =108/(108+O7) -> 1 | W7: =(U7+V7)/2 -> 0.66129032
A9: All
B10: Predicted Pcs | C10: True positive | D10: false positives | E10: true negatives | F10: false negatives | G10: false positive rate | H10: false negative rate | I10: precision | J10: recall | K10: specificity | L10: balanced accuracy | M10: Predicted Pcs | N10: Correct Pcs | O10: false positives | P10: true negatives | Q10: false negatives | R10: false positive rate | S10: false negative rate | U10: recall | V10: specificity | W10: balanced accuracy
A11: 0.5 | B11: =[1]SCOPE!B11+[1]HICEAS17!B11+[1]HICEAS23!B11 -> 133 | C11: =[1]SCOPE!C11+[1]HICEAS17!C11+[1]HICEAS23!C11 -> 57 | D11: =[1]SCOPE!D11+[1]HICEAS17!D11+[1]HICEAS23!D11 -> 74 | E11: =108+486+337 -> 931 | F11: =[1]SCOPE!E11+[1]HICEAS17!E11+[1]HICEAS23!E11 -> 0 | G11: =D11/(D11+E11) -> 0.073631841 | H11: =F11/(C11+F11) -> 0 | I11: =C11/(C11+D11) -> 0.4351145 | J11: =C11/(C11+F11) -> 1 | K11: =108/(108+D11) -> 0.59340659 | L11: =(J11+K11)/2 -> 0.7967033 | M11: =[1]SCOPE!L11+[1]HICEAS17!L11+[1]HICEAS23!L11 -> 57 | N11: =[1]SCOPE!M11+[1]HICEAS17!M11+[1]HICEAS23!M11 -> 57 | O11: =[1]SCOPE!N11+[1]HICEAS17!N11+[1]HICEAS23!N11 -> 0 | P11: =108+486+337 -> 931 | Q11: =[1]SCOPE!O11+[1]HICEAS17!O11+[1]HICEAS23!O11 -> 0 | R11: =O11/(O11+P11) -> 0 | S11: =Q11/(N11+Q11) -> 0 | T11: =N11/(N11+O11) -> 1 | U11: =N11/(N11+Q11) -> 1 | V11: =108/(108+O11) -> 1 | W11: =(U11+V11)/2 -> 1
A12: 0.6 | B12: =[1]SCOPE!B12+[1]HICEAS17!B12+[1]HICEAS23!B12 -> 95 | C12: =[1]SCOPE!C12+[1]HICEAS17!C12+[1]HICEAS23!C12 -> 52 | D12: =[1]SCOPE!D12+[1]HICEAS17!D12+[1]HICEAS23!D12 -> 41 | E12: =108+486+337 -> 931 | F12: =[1]SCOPE!E12+[1]HICEAS17!E12+[1]HICEAS23!E12 -> 5 | G12: =D12/(D12+E12) -> 0.04218107 | H12: =F12/(C12+F12) -> 0.087719298 | I12: =C12/(C12+D12) -> 0.55913978 | J12: =C12/(C12+F12) -> 0.9122807 | K12: =108/(108+D12) -> 0.72483221 | L12: =(J12+K12)/2 -> 0.81855646 | M12: =[1]SCOPE!L12+[1]HICEAS17!L12+[1]HICEAS23!L12 -> 52 | N12: =[1]SCOPE!M12+[1]HICEAS17!M12+[1]HICEAS23!M12 -> 52 | O12: =[1]SCOPE!N12+[1]HICEAS17!N12+[1]HICEAS23!N12 -> 0 | P12: =108+486+337 -> 931 | Q12: =[1]SCOPE!O12+[1]HICEAS17!O12+[1]HICEAS23!O12 -> 5 | R12: =O12/(O12+P12) -> 0 | S12: =Q12/(N12+Q12) -> 0.087719298 | T12: =N12/(N12+O12) -> 1 | U12: =N12/(N12+Q12) -> 0.9122807 | V12: =108/(108+O12) -> 1 | W12: =(U12+V12)/2 -> 0.95614035
A13: 0.7 | B13: =[1]SCOPE!B13+[1]HICEAS17!B13+[1]HICEAS23!B13 -> 69 | C13: =[1]SCOPE!C13+[1]HICEAS17!C13+[1]HICEAS23!C13 -> 45 | D13: =[1]SCOPE!D13+[1]HICEAS17!D13+[1]HICEAS23!D13 -> 22 | E13: =108+486+337 -> 931 | F13: =[1]SCOPE!E13+[1]HICEAS17!E13+[1]HICEAS23!E13 -> 12 | G13: =D13/(D13+E13) -> 0.023084995 | H13: =F13/(C13+F13) -> 0.21052632 | I13: =C13/(C13+D13) -> 0.67164179 | J13: =C13/(C13+F13) -> 0.78947368 | K13: =108/(108+D13) -> 0.83076923 | L13: =(J13+K13)/2 -> 0.81012146 | M13: =[1]SCOPE!L13+[1]HICEAS17!L13+[1]HICEAS23!L13 -> 45 | N13: =[1]SCOPE!M13+[1]HICEAS17!M13+[1]HICEAS23!M13 -> 45 | O13: =[1]SCOPE!N13+[1]HICEAS17!N13+[1]HICEAS23!N13 -> 0 | P13: =108+486+337 -> 931 | Q13: =[1]SCOPE!O13+[1]HICEAS17!O13+[1]HICEAS23!O13 -> 12 | R13: =O13/(O13+P13) -> 0 | S13: =Q13/(N13+Q13) -> 0.21052632 | T13: =N13/(N13+O13) -> 1 | U13: =N13/(N13+Q13) -> 0.78947368 | V13: =108/(108+O13) -> 1 | W13: =(U13+V13)/2 -> 0.89473684
A14: 0.8 | B14: =[1]SCOPE!B14+[1]HICEAS17!B14+[1]HICEAS23!B14 -> 39 | C14: =[1]SCOPE!C14+[1]HICEAS17!C14+[1]HICEAS23!C14 -> 35 | D14: =[1]SCOPE!D14+[1]HICEAS17!D14+[1]HICEAS23!D14 -> 4 | E14: =108+486+337 -> 931 | F14: =[1]SCOPE!E14+[1]HICEAS17!E14+[1]HICEAS23!E14 -> 22 | G14: =D14/(D14+E14) -> 0.0042780749 | H14: =F14/(C14+F14) -> 0.38596491 | I14: =C14/(C14+D14) -> 0.8974359 | J14: =C14/(C14+F14) -> 0.61403509 | K14: =108/(108+D14) -> 0.96428571 | L14: =(J14+K14)/2 -> 0.7891604 | M14: =[1]SCOPE!L14+[1]HICEAS17!L14+[1]HICEAS23!L14 -> 35 | N14: =[1]SCOPE!M14+[1]HICEAS17!M14+[1]HICEAS23!M14 -> 35 | O14: =[1]SCOPE!N14+[1]HICEAS17!N14+[1]HICEAS23!N14 -> 0 | P14: =108+486+337 -> 931 | Q14: =[1]SCOPE!O14+[1]HICEAS17!O14+[1]HICEAS23!O14 -> 22 | R14: =O14/(O14+P14) -> 0 | S14: =Q14/(N14+Q14) -> 0.38596491 | T14: =N14/(N14+O14) -> 1 | U14: =N14/(N14+Q14) -> 0.61403509 | V14: =108/(108+O14) -> 1 | W14: =(U14+V14)/2 -> 0.80701754
A15: 0.9 | B15: =[1]SCOPE!B15+[1]HICEAS17!B15+[1]HICEAS23!B15 -> 12 | C15: =[1]SCOPE!C15+[1]HICEAS17!C15+[1]HICEAS23!C15 -> 12 | D15: =[1]SCOPE!D15+[1]HICEAS17!D15+[1]HICEAS23!D15 -> 0 | E15: =108+486+337 -> 931 | F15: =[1]SCOPE!E15+[1]HICEAS17!E15+[1]HICEAS23!E15 -> 45 | G15: =D15/(D15+E15) -> 0 | H15: =F15/(C15+F15) -> 0.78947368 | I15: =C15/(C15+D15) -> 1 | J15: =C15/(C15+F15) -> 0.21052632 | K15: =108/(108+D15) -> 1 | L15: =(J15+K15)/2 -> 0.60526316 | M15: =[1]SCOPE!L15+[1]HICEAS17!L15+[1]HICEAS23!L15 -> 12 | N15: =[1]SCOPE!M15+[1]HICEAS17!M15+[1]HICEAS23!M15 -> 12 | O15: =[1]SCOPE!N15+[1]HICEAS17!N15+[1]HICEAS23!N15 -> 0 | P15: =108+486+337 -> 931 | Q15: =[1]SCOPE!O15+[1]HICEAS17!O15+[1]HICEAS23!O15 -> 45 | R15: =O15/(O15+P15) -> 0 | S15: =Q15/(N15+Q15) -> 0.78947368 | T15: =N15/(N15+O15) -> 1 | U15: =N15/(N15+Q15) -> 0.21052632 | V15: =108/(108+O15) -> 1 | W15: =(U15+V15)/2 -> 0.60526316

Sheet ALL_SCORES
A1: TP | B1: FP | C1: Filename | D1: event.id | E1: predicted | F1: X33 | G1: X577 | H1: original | I1: correct | K1: True Negatives = 486
A2: v | C2: 305 | D2: 1705416 | E2: X33 | F2: 0.9954 | G2: 0.0046 | H2: X33 | I2: TRUE | K2: 1706259 DW only. Do not use in analysis. No valid EC Data, which is probably lowering the score. Update: 4/7/25 This is a mixed species encounter with AC258 and the ship is not at full speed.
A3: v | C3: 93 | D3: 1705109 | E3: X33 | F3: 0.9857 | G3: 0.0143 | H3: X33 | I3: TRUE | K3: Red cells indicate AC-ONLY events that did not pass both filters
A4: v | C4: 16 | D4: 2404021 | E4: X33 | F4: 0.9455 | G4: 0.0545 | H4: X33 | I4: TRUE | K4: Green cells indicate events that should technically be included based on filters.
A5: v | C5: 238 | D5: 2303309 | E5: X33 | F5: 0.9367 | G5: 0.0633 | H5: X33 | I5: TRUE
A6: v | C6: 236 | D6: 1706298 | E6: X33 | F6: 0.9301 | G6: 0.0699 | H6: X33 | I6: TRUE
A7: a | C7: 47 | D7: 2303056 | E7: X33 | F7: 0.9256 | G7: 0.0744 | H7: X277 | I7: FALSE | J7: AC
A8: v | C8: 65 | D8: 2404091 | E8: X33 | F8: 0.9194 | G8: 0.0806 | H8: X33 | I8: TRUE
A9: a | C9: 245 | D9: 1705307 | E9: X33 | F9: 0.9145 | G9: 0.0855 | H9: X277 | I9: FALSE | J9: AC | K9: EC>22 khz but whistles are good | N9: kept | O9: Changed case_studies_all_data_2026-01-03-Jen.csv
A10: v | C10: 118 | D10: 2303155 | E10: X33 | F10: 0.912 | G10: 0.088 | H10: X33 | I10: TRUE
A11: v | C11: 91 | D11: 2404128 | E11: X33 | F11: 0.9064 | G11: 0.0936 | H11: X33 | I11: TRUE
A12: v | C12: 65 | D12: 1706081 | E12: X33 | F12: 0.9045 | G12: 0.0955 | H12: X33 | I12: TRUE
A13: v | C13: 246 | D13: 1705308 | E13: X33 | F13: 0.904 | G13: 0.096 | H13: X33 | I13: TRUE
A14: a | C14: 13 | D14: 2404018 | E14: X33 | F14: 0.8893 | G14: 0.1107 | H14: X33 | I14: FALSE | J14: AC
A15: a | C15: 278 | D15: 2303356 | E15: X33 | F15: 0.887 | G15: 0.113 | H15: X377 | I15: FALSE | J15: AC
A16: v | C16: 92 | D16: 1705108 | E16: X33 | F16: 0.8837 | G16: 0.1163 | H16: X33 | I16: TRUE
A17: a | C17: 286 | D17: 1705385 | E17: X33 | F17: 0.8813 | G17: 0.1187 | H17: X77 | I17: FALSE | J17: AC
B18: a | C18: 234 | D18: 1706296 | E18: X33 | F18: 0.8738 | G18: 0.1262 | H18: X77 | I18: FALSE | J18: NO | K18: Not enough signals (<10). DW do look possible.
A19: v | C19: 72 | D19: 1706091 | E19: X33 | F19: 0.8715 | G19: 0.1285 | H19: X33 | I19: TRUE
A20: v | C20: 4 | D20: 1706007 | E20: X33 | F20: 0.8711 | G20: 0.1289 | H20: X33 | I20: TRUE
A21: v | C21: 233 | D21: 1705280 | E21: X33 | F21: 0.8693 | G21: 0.1307 | H21: X33 | I21: TRUE
A22: a | C22: 66 | D22: 1705075 | E22: X33 | F22: 0.8686 | G22: 0.1314 | H22: X77 | I22: FALSE | J22: AC | K22: EC>22 khz but whistles are good | N22: kept
A23: v | C23: 89 | D23: 2404126 | E23: X33 | F23: 0.8657 | G23: 0.1343 | H23: X33 | I23: TRUE
A24: v | C24: 230 | D24: 1705276 | E24: X33 | F24: 0.8639 | G24: 0.1361 | H24: X33 | I24: TRUE
A25: v | C25: 232 | D25: 1705279 | E25: X33 | F25: 0.8606 | G25: 0.1394 | H25: X33 | I25: TRUE
B26: a | C26: 254 | D26: 2303331 | E26: X33 | F26: 0.8538 | G26: 0.1462 | H26: X277 | I26: FALSE | J26: NO | K26: Blackfish, but the DW in Pc range is actually the Sette noise. Issue with the rutter.
A27: v | C27: 15 | D27: 1705016 | E27: X33 | F27: 0.8536 | G27: 0.1464 | H27: X33 | I27: TRUE
A28: v | C28: 59 | D28: 1705067 | E28: X33 | F28: 0.8512 | G28: 0.1488 | H28: X33 | I28: TRUE
A29: a | C29: 175 | D29: 1705210 | E29: X33 | F29: 0.8477 | G29: 0.1523 | H29: X33 | I29: FALSE | J29: AC | K29: Pc before turn for Spotters | L29: EC>22 khz but whistles are good | N29: kept
A30: a | C30: 237 | D30: 1705292 | E30: X33 | F30: 0.8434 | G30: 0.1566 | H30: X77 | I30: FALSE | J30: AC
B31: a | C31: 225 | D31: 1706279 | E31: X33 | F31: 0.8373 | G31: 0.1627 | H31: X77 | I31: FALSE | J31: NO | K31: Not enough signals (<5). DW do look possible.
A32: v | C32: 81 | D32: 1706101 | E32: X33 | F32: 0.8338 | G32: 0.1662 | H32: X33 | I32: TRUE
B33: a | C33: 231 | D33: 2303302 | E33: X33 | F33: 0.8324 | G33: 0.1676 | H33: X77 | I33: FALSE | J33: NO | K33: Not enough signals.
A34: v | C34: 227 | D34: 1706281 | E34: X33 | F34: 0.8304 | G34: 0.1696 | H34: X33 | I34: TRUE
A35: a | C35: 216 | D35: 1706269 | E35: X33 | F35: 0.8261 | G35: 0.1739 | H35: X77 | I35: FALSE | J35: AC
A36: v | C36: 233 | D36: 1706295 | E36: X33 | F36: 0.8256 | G36: 0.1744 | H36: X33 | I36: TRUE
A37: a | C37: 105 | D37: 1706127 | E37: X33 | F37: 0.8172 | G37: 0.1828 | H37: X77 | I37: FALSE | J37: AC
A38: a | C38: 50 | D38: 2404070 | E38: X33 | F38: 0.8143 | G38: 0.1857 | H38: X33 | I38: TRUE | J38: AC
A39: a | C39: 183 | D39: 1706132 | E39: X33 | F39: 0.8098 | G39: 0.1902 | H39: X77 | I39: FALSE | J39: AC
A40: v | C40: 209 | D40: 1706256 | E40: X33 | F40: 0.8091 | G40: 0.1909 | H40: X33 | I40: TRUE
...

Sheet HICEAS17
A1: Visuals only | L1: MDF + SSF
B2: Predicted Pcs | C2: True positive | D2: false positives | E2: false negatives | F2: false positive rate | G2: false negative rate | H2: precision | I2: recall | J2: specificity | K2: balanced accuracy | L2: Predicted Pcs | M2: Correct Pcs | N2: false positives | O2: false negatives | P2: false positive rate | Q2: false negative rate | R2: precision | S2: recall | T2: specificity | U2: balanced accuracy
A3: 0.5 | B3: 21 | C3: 21 | D3: 0 | E3: 0 | F3: =D3/(D3+486) -> 0 | G3: =E3/(C3+E3) -> 0 | H3: =C3/(C3+D3) -> 1 | I3: =C3/(C3+E3) -> 1 | J3: =108/(108+D3) -> 1 | K3: =(I3+J3)/2 -> 1 | L3: 21 | M3: 21 | N3: 0 | O3: 0 | P3: =N3/(N3+486) -> 0 | Q3: =O3/(M3+O3) -> 0 | R3: =M3/(M3+N3) -> 1 | S3: =M3/(M3+O3) -> 1 | T3: =108/(108+N3) -> 1 | U3: =(S3+T3)/2 -> 1
A4: 0.6 | B4: 21 | C4: 21 | D4: 0 | E4: 0 | F4: =D4/(D4+486) -> 0 | G4: =E4/(C4+E4) -> 0 | H4: =C4/(C4+D4) -> 1 | I4: =C4/(C4+E4) -> 1 | J4: =108/(108+D4) -> 1 | K4: =(I4+J4)/2 -> 1 | L4: 21 | M4: 21 | N4: 0 | O4: 0 | P4: =N4/(N4+486) -> 0 | Q4: =O4/(M4+O4) -> 0 | R4: =M4/(M4+N4) -> 1 | S4: =M4/(M4+O4) -> 1 | T4: =108/(108+N4) -> 1 | U4: =(S4+T4)/2 -> 1
A5: 0.7 | B5: 20 | C5: 20 | D5: 0 | E5: 1 | F5: =D5/(D5+486) -> 0 | G5: =E5/(C5+E5) -> 0.047619048 | H5: =C5/(C5+D5) -> 1 | I5: =C5/(C5+E5) -> 0.95238095 | J5: =108/(108+D5) -> 1 | K5: =(I5+J5)/2 -> 0.97619048 | L5: 20 | M5: 20 | N5: 0 | O5: 1 | P5: =N5/(N5+486) -> 0 | Q5: =O5/(M5+O5) -> 0.047619048 | R5: =M5/(M5+N5) -> 1 | S5: =M5/(M5+O5) -> 0.95238095 | T5: =108/(108+N5) -> 1 | U5: =(S5+T5)/2 -> 0.97619048
A6: 0.8 | B6: 17 | C6: 17 | D6: 0 | E6: 4 | F6: =D6/(D6+486) -> 0 | G6: =E6/(C6+E6) -> 0.19047619 | H6: =C6/(C6+D6) -> 1 | I6: =C6/(C6+E6) -> 0.80952381 | J6: =108/(108+D6) -> 1 | K6: =(I6+J6)/2 -> 0.9047619 | L6: 17 | M6: 17 | N6: 0 | O6: 4 | P6: =N6/(N6+486) -> 0 | Q6: =O6/(M6+O6) -> 0.19047619 | R6: =M6/(M6+N6) -> 1 | S6: =M6/(M6+O6) -> 0.80952381 | T6: =108/(108+N6) -> 1 | U6: =(S6+T6)/2 -> 0.9047619
A7: 0.9 | B7: 5 | C7: 5 | D7: 0 | E7: 16 | F7: =D7/(D7+486) -> 0 | G7: =E7/(C7+E7) -> 0.76190476 | H7: =C7/(C7+D7) -> 1 | I7: =C7/(C7+E7) -> 0.23809524 | J7: =108/(108+D7) -> 1 | K7: =(I7+J7)/2 -> 0.61904762 | L7: 5 | M7: 5 | N7: 0 | O7: 16 | P7: =N7/(N7+486) -> 0 | Q7: =O7/(M7+O7) -> 0.76190476 | R7: =M7/(M7+N7) -> 1 | S7: =M7/(M7+O7) -> 0.23809524 | T7: =108/(108+N7) -> 1 | U7: =(S7+T7)/2 -> 0.61904762
A9: Both
B10: Predicted Pcs | C10: True positive | D10: false positives | E10: false negatives | F10: false positive rate | G10: false negative rate | H10: precision | I10: recall | J10: specificity | K10: balanced accuracy | L10: Predicted Pcs | M10: Correct Pcs | N10: false positives | O10: false negatives | P10: false positive rate | Q10: false negative rate | S10: recall | T10: specificity | U10: balanced accuracy
A11: 0.5 | B11: 68 | C11: 33 | D11: 35 | E11: 0 | F11: =D11/(D11+486) -> 0.067178503 | G11: =E11/(C11+E11) -> 0 | H11: =C11/(C11+D11) -> 0.48529412 | I11: =C11/(C11+E11) -> 1 | J11: =108/(108+D11) -> 0.75524476 | K11: =(I11+J11)/2 -> 0.87762238 | L11: 33 | M11: 33 | N11: 0 | O11: 0 | P11: =N11/(N11+486) -> 0 | Q11: =O11/(M11+O11) -> 0 | R11: =M11/(M11+N11) -> 1 | S11: =M11/(M11+O11) -> 1 | T11: =108/(108+N11) -> 1 | U11: =(S11+T11)/2 -> 1
A12: 0.6 | B12: 54 | C12: 33 | D12: 21 | E12: 0 | F12: =D12/(D12+486) -> 0.041420118 | G12: =E12/(C12+E12) -> 0 | H12: =C12/(C12+D12) -> 0.61111111 | I12: =C12/(C12+E12) -> 1 | J12: =108/(108+D12) -> 0.8372093 | K12: =(I12+J12)/2 -> 0.91860465 | L12: 33 | M12: 33 | N12: 0 | O12: 0 | P12: =N12/(N12+486) -> 0 | Q12: =O12/(M12+O12) -> 0 | R12: =M12/(M12+N12) -> 1 | S12: =M12/(M12+O12) -> 1 | T12: =108/(108+N12) -> 1 | U12: =(S12+T12)/2 -> 1
A13: 0.7 | B13: 39 | C13: 29 | D13: 10 | E13: 4 | F13: =D13/(D13+486) -> 0.02016129 | G13: =E13/(C13+E13) -> 0.12121212 | H13: =C13/(C13+D13) -> 0.74358974 | I13: =C13/(C13+E13) -> 0.87878788 | J13: =108/(108+D13) -> 0.91525424 | K13: =(I13+J13)/2 -> 0.89702106 | L13: 29 | M13: 29 | N13: 0 | O13: 4 | P13: =N13/(N13+486) -> 0 | Q13: =O13/(M13+O13) -> 0.12121212 | R13: =O13/(O13+N13) -> 1 | S13: =M13/(M13+O13) -> 0.87878788 | T13: =108/(108+N13) -> 1 | U13: =(S13+T13)/2 -> 0.93939394
A14: 0.8 | B14: 27 | C14: 25 | D14: 2 | E14: 8 | F14: =D14/(D14+486) -> 0.0040983607 | G14: =E14/(C14+E14) -> 0.24242424 | H14: =C14/(C14+D14) -> 0.92592593 | I14: =C14/(C14+E14) -> 0.75757576 | J14: =108/(108+D14) -> 0.98181818 | K14: =(I14+J14)/2 -> 0.86969697 | L14: 25 | M14: 25 | N14: 0 | O14: 8 | P14: =N14/(N14+486) -> 0 | Q14: =O14/(M14+O14) -> 0.24242424 | R14: =M14/(M14+N14) -> 1 | S14: =M14/(M14+O14) -> 0.75757576 | T14: =108/(108+N14) -> 1 | U14: =(S14+T14)/2 -> 0.87878788
A15: 0.9 | B15: 6 | C15: 6 | D15: 0 | E15: 27 | F15: =D15/(D15+486) -> 0 | G15: =E15/(C15+E15) -> 0.81818182 | H15: =C15/(C15+D15) -> 1 | I15: =C15/(C15+E15) -> 0.18181818 | J15: =108/(108+D15) -> 1 | K15: =(I15+J15)/2 -> 0.59090909 | L15: 6 | M15: 6 | N15: 0 | O15: 27 | P15: =N15/(N15+486) -> 0 | Q15: =O15/(M15+O15) -> 0.81818182 | R15: =M15/(M15+N15) -> 1 | S15: =M15/(M15+O15) -> 0.18181818 | T15: =108/(108+N15) -> 1 | U15: =(S15+T15)/2 -> 0.59090909

Sheet HICEAS23
A1: Visuals only | L1: MDF + SSF
B2: Predicted Pcs | C2: True positive | D2: false positives | E2: false negatives | F2: false positive rate | G2: false negative rate | H2: precision | I2: recall | J2: specificity | K2: balanced accuracy | L2: Predicted Pcs | M2: Correct Pcs | N2: false positives | O2: false negatives | P2: false positive rate | Q2: false negative rate | R2: precision | S2: recall | T2: specificity | U2: balanced accuracy
A3: 0.5 | B3: 11 | C3: 5 | D3: 6 | E3: 0 | F3: =D3/(D3+337) -> 0.017492711 | G3: =E3/(C3+E3) -> 0 | H3: =C3/(C3+D3) -> 0.45454545 | I3: =C3/(C3+E3) -> 1 | J3: =108/(108+D3) -> 0.94736842 | K3: =(I3+J3)/2 -> 0.97368421 | L3: 5 | M3: 5 | N3: 0 | O3: 0 | P3: =N3/(N3+337) -> 0 | Q3: =O3/(M3+O3) -> 0 | R3: =M3/(M3+N3) -> 1 | S3: =M3/(M3+O3) -> 1 | T3: =108/(108+N3) -> 1 | U3: =(S3+T3)/2 -> 1
A4: 0.6 | B4: 6 | C4: 5 | D4: 1 | E4: 0 | F4: =D4/(D4+337) -> 0.0029585799 | G4: =E4/(C4+E4) -> 0 | H4: =C4/(C4+D4) -> 0.83333333 | I4: =C4/(C4+E4) -> 1 | J4: =108/(108+D4) -> 0.99082569 | K4: =(I4+J4)/2 -> 0.99541284 | L4: 5 | M4: 5 | N4: 0 | O4: 0 | P4: =N4/(N4+337) -> 0 | Q4: =O4/(M4+O4) -> 0 | R4: =M4/(M4+N4) -> 1 | S4: =M4/(M4+O4) -> 1 | T4: =108/(108+N4) -> 1 | U4: =(S4+T4)/2 -> 1
A5: 0.7 | B5: 6 | C5: 5 | D5: 1 | E5: 0 | F5: =D5/(D5+337) -> 0.0029585799 | G5: =E5/(C5+E5) -> 0 | H5: =C5/(C5+D5) -> 0.83333333 | I5: =C5/(C5+E5) -> 1 | J5: =108/(108+D5) -> 0.99082569 | K5: =(I5+J5)/2 -> 0.99541284 | L5: 5 | M5: 5 | N5: 0 | O5: 0 | P5: =N5/(N5+337) -> 0 | Q5: =O5/(M5+O5) -> 0 | R5: =M5/(M5+N5) -> 1 | S5: =M5/(M5+O5) -> 1 | T5: =108/(108+N5) -> 1 | U5: =(S5+T5)/2 -> 1
A6: 0.8 | B6: 2 | C6: 2 | D6: 0 | E6: 3 | F6: =D6/(D6+337) -> 0 | G6: =E6/(C6+E6) -> 0.6 | H6: =C6/(C6+D6) -> 1 | I6: =C6/(C6+E6) -> 0.4 | J6: =108/(108+D6) -> 1 | K6: =(I6+J6)/2 -> 0.7 | L6: 2 | M6: 2 | N6: 0 | O6: 3 | P6: =N6/(N6+337) -> 0 | Q6: =O6/(M6+O6) -> 0.6 | R6: =M6/(M6+N6) -> 1 | S6: =M6/(M6+O6) -> 0.4 | T6: =108/(108+N6) -> 1 | U6: =(S6+T6)/2 -> 0.7
A7: 0.9 | B7: 2 | C7: 2 | D7: 0 | E7: 3 | F7: =D7/(D7+337) -> 0 | G7: =E7/(C7+E7) -> 0.6 | H7: =C7/(C7+D7) -> 1 | I7: =C7/(C7+E7) -> 0.4 | J7: =108/(108+D7) -> 1 | K7: =(I7+J7)/2 -> 0.7 | L7: 2 | M7: 2 | N7: 0 | O7: 3 | P7: =N7/(N7+337) -> 0 | Q7: =O7/(M7+O7) -> 0.6 | R7: =M7/(M7+N7) -> 1 | S7: =M7/(M7+O7) -> 0.4 | T7: =108/(108+N7) -> 1 | U7: =(S7+T7)/2 -> 0.7
A9: Both
B10: Predicted Pcs | C10: True positive | D10: false positives | E10: false negatives | F10: false positive rate | G10: false negative rate | H10: precision | I10: recall | J10: specificity | K10: balanced accuracy | L10: Predicted Pcs | M10: Correct Pcs | N10: false positives | O10: false negatives | P10: false positive rate | Q10: false negative rate | S10: recall | T10: specificity | U10: balanced accuracy
A11: 0.5 | B11: 51 | C11: 14 | D11: 35 | E11: 0 | F11: =D11/(D11+337) -> 0.094086022 | G11: =E11/(C11+E11) -> 0 | H11: =C11/(C11+D11) -> 0.28571429 | I11: =C11/(C11+E11) -> 1 | J11: =108/(108+D11) -> 0.75524476 | K11: =(I11+J11)/2 -> 0.87762238 | L11: 14 | M11: 14 | N11: 0 | O11: 0 | P11: =N11/(N11+337) -> 0 | Q11: =O11/(M11+O11) -> 0 | R11: =M11/(M11+N11) -> 1 | S11: =M11/(M11+O11) -> 1 | T11: =108/(108+N11) -> 1 | U11: =(S11+T11)/2 -> 1
A12: 0.6 | B12: 31 | C12: 10 | D12: 19 | E12: 4 | F12: =D12/(D12+337) -> 0.053370787 | G12: =E12/(C12+E12) -> 0.28571429 | H12: =C12/(C12+D12) -> 0.34482759 | I12: =C12/(C12+E12) -> 0.71428571 | J12: =108/(108+D12) -> 0.8503937 | K12: =(I12+J12)/2 -> 0.78233971 | L12: 10 | M12: 10 | N12: 0 | O12: 4 | P12: =N12/(N12+337) -> 0 | Q12: =O12/(M12+O12) -> 0.28571429 | R12: =M12/(M12+N12) -> 1 | S12: =M12/(M12+O12) -> 0.71428571 | T12: =108/(108+N12) -> 1 | U12: =(S12+T12)/2 -> 0.85714286
A13: 0.7 | B13: 21 | C13: 8 | D13: 11 | E13: 6 | F13: =D13/(D13+337) -> 0.031609195 | G13: =E13/(C13+E13) -> 0.42857143 | H13: =C13/(C13+D13) -> 0.42105263 | I13: =C13/(C13+E13) -> 0.57142857 | J13: =108/(108+D13) -> 0.90756303 | K13: =(I13+J13)/2 -> 0.7394958 | L13: 8 | M13: 8 | N13: 0 | O13: 6 | P13: =N13/(N13+337) -> 0 | Q13: =O13/(M13+O13) -> 0.42857143 | R13: =O13/(O13+N13) -> 1 | S13: =M13/(M13+O13) -> 0.57142857 | T13: =108/(108+N13) -> 1 | U13: =(S13+T13)/2 -> 0.78571429
A14: 0.8 | B14: 6 | C14: 4 | D14: 2 | E14: 10 | F14: =D14/(D14+337) -> 0.005899705 | G14: =E14/(C14+E14) -> 0.71428571 | H14: =C14/(C14+D14) -> 0.66666667 | I14: =C14/(C14+E14) -> 0.28571429 | J14: =108/(108+D14) -> 0.98181818 | K14: =(I14+J14)/2 -> 0.63376623 | L14: 4 | M14: 4 | N14: 0 | O14: 10 | P14: =N14/(N14+337) -> 0 | Q14: =O14/(M14+O14) -> 0.71428571 | R14: =M14/(M14+N14) -> 1 | S14: =M14/(M14+O14) -> 0.28571429 | T14: =108/(108+N14) -> 1 | U14: =(S14+T14)/2 -> 0.64285714
A15: 0.9 | B15: 3 | C15: 3 | D15: 0 | E15: 11 | F15: =D15/(D15+337) -> 0 | G15: =E15/(C15+E15) -> 0.78571429 | H15: =C15/(C15+D15) -> 1 | I15: =C15/(C15+E15) -> 0.21428571 | J15: =108/(108+D15) -> 1 | K15: =(I15+J15)/2 -> 0.60714286 | L15: 3 | M15: 3 | N15: 0 | O15: 11 | P15: =N15/(N15+337) -> 0 | Q15: =O15/(M15+O15) -> 0.78571429 | R15: =M15/(M15+N15) -> 1 | S15: =M15/(M15+O15) -> 0.21428571 | T15: =108/(108+N15) -> 1 | U15: =(S15+T15)/2 -> 0.60714286

Sheet SCOPE
A1: Visuals only | L1: MDF + SSF
B2: Predicted Pcs | C2: True positive | D2: false positives | E2: false negatives | F2: false positive rate | G2: false negative rate | H2: precision | I2: recall | J2: specificity | K2: balanced accuracy | L2: Predicted Pcs | M2: Correct Pcs | N2: false positives | O2: false negatives | P2: false positive rate | Q2: false negative rate | R2: precision | S2: recall | T2: specificity | U2: balanced accuracy
A3: 0.5 | B3: 8 | C3: 5 | D3: 3 | E3: 0 | F3: =D3/(D3+108) -> 0.027027027 | G3: =E3/(C3+E3) -> 0 | H3: =C3/(C3+D3) -> 0.625 | I3: =C3/(C3+E3) -> 1 | J3: =108/(108+D3) -> 0.97297297 | K3: =(I3+J3)/2 -> 0.98648649 | L3: 5 | M3: 5 | N3: 0 | O3: 0 | P3: =N3/(N3+108) -> 0 | Q3: =O3/(M3+O3) -> 0 | R3: =M3/(M3+N3) -> 1 | S3: =M3/(M3+O3) -> 1 | T3: =108/(108+N3) -> 1 | U3: =(S3+T3)/2 -> 1
A4: 0.6 | B4: 5 | C4: 4 | D4: 1 | E4: 1 | F4: =D4/(D4+108) -> 0.0091743119 | G4: =E4/(C4+E4) -> 0.2 | H4: =C4/(C4+D4) -> 0.8 | I4: =C4/(C4+E4) -> 0.8 | J4: =108/(108+D4) -> 0.99082569 | K4: =(I4+J4)/2 -> 0.89541284 | L4: 4 | M4: 4 | N4: 0 | O4: 1 | P4: =N4/(N4+108) -> 0 | Q4: =O4/(M4+O4) -> 0.2 | R4: =M4/(M4+N4) -> 1 | S4: =M4/(M4+O4) -> 0.8 | T4: =108/(108+N4) -> 1 | U4: =(S4+T4)/2 -> 0.9
A5: 0.7 | B5: 5 | C5: 4 | D5: 1 | E5: 1 | F5: =D5/(D5+108) -> 0.0091743119 | G5: =E5/(C5+E5) -> 0.2 | H5: =C5/(C5+D5) -> 0.8 | I5: =C5/(C5+E5) -> 0.8 | J5: =108/(108+D5) -> 0.99082569 | K5: =(I5+J5)/2 -> 0.89541284 | L5: 4 | M5: 4 | N5: 0 | O5: 1 | P5: =N5/(N5+108) -> 0 | Q5: =O5/(M5+O5) -> 0.2 | R5: =M5/(M5+N5) -> 1 | S5: =M5/(M5+O5) -> 0.8 | T5: =108/(108+N5) -> 1 | U5: =(S5+T5)/2 -> 0.9
A6: 0.8 | B6: 4 | C6: 4 | D6: 0 | E6: 1 | F6: =D6/(D6+108) -> 0 | G6: =E6/(C6+E6) -> 0.2 | H6: =C6/(C6+D6) -> 1 | I6: =C6/(C6+E6) -> 0.8 | J6: =108/(108+D6) -> 1 | K6: =(I6+J6)/2 -> 0.9 | L6: 4 | M6: 4 | N6: 0 | O6: 1 | P6: =N6/(N6+108) -> 0 | Q6: =O6/(M6+O6) -> 0.2 | R6: =M6/(M6+N6) -> 1 | S6: =M6/(M6+O6) -> 0.8 | T6: =108/(108+N6) -> 1 | U6: =(S6+T6)/2 -> 0.9
A7: 0.9 | B7: 3 | C7: 3 | D7: 0 | E7: 2 | F7: =D7/(D7+108) -> 0 | G7: =E7/(C7+E7) -> 0.4 | H7: =C7/(C7+D7) -> 1 | I7: =C7/(C7+E7) -> 0.6 | J7: =108/(108+D7) -> 1 | K7: =(I7+J7)/2 -> 0.8 | L7: 3 | M7: 3 | N7: 0 | O7: 2 | P7: =N7/(N7+108) -> 0 | Q7: =O7/(M7+O7) -> 0.4 | R7: =M7/(M7+N7) -> 1 | S7: =M7/(M7+O7) -> 0.6 | T7: =108/(108+N7) -> 1 | U7: =(S7+T7)/2 -> 0.8
A9: Both
B10: Predicted Pcs | C10: True positive | D10: false positives | E10: false negatives | F10: false positive rate | G10: false negative rate | H10: precision | I10: recall | J10: specificity | K10: balanced accuracy | L10: Predicted Pcs | M10: Correct Pcs | N10: false positives | O10: false negatives | P10: false positive rate | Q10: false negative rate | S10: recall | T10: specificity | U10: balanced accuracy
A11: 0.5 | B11: 14 | C11: 10 | D11: 4 | E11: 0 | F11: =D11/(D11+108) -> 0.035714286 | G11: =E11/(C11+E11) -> 0 | H11: =C11/(C11+D11) -> 0.71428571 | I11: =C11/(C11+E11) -> 1 | J11: =108/(108+D11) -> 0.96428571 | K11: =(I11+J11)/2 -> 0.98214286 | L11: 10 | M11: 10 | N11: 0 | O11: 0 | P11: =N11/(N11+108) -> 0 | Q11: =O11/(M11+O11) -> 0 | R11: =M11/(M11+N11) -> 1 | S11: =M11/(M11+O11) -> 1 | T11: =108/(108+N11) -> 1 | U11: =(S11+T11)/2 -> 1
A12: 0.6 | B12: 10 | C12: 9 | D12: 1 | E12: 1 | F12: =D12/(D12+108) -> 0.0091743119 | G12: =E12/(C12+E12) -> 0.1 | H12: =C12/(C12+D12) -> 0.9 | I12: =C12/(C12+E12) -> 0.9 | J12: =108/(108+D12) -> 0.99082569 | K12: =(I12+J12)/2 -> 0.94541284 | L12: 9 | M12: 9 | N12: 0 | O12: 1 | P12: =N12/(N12+108) -> 0 | Q12: =O12/(M12+O12) -> 0.1 | R12: =M12/(M12+N12) -> 1 | S12: =M12/(M12+O12) -> 0.9 | T12: =108/(108+N12) -> 1 | U12: =(S12+T12)/2 -> 0.95
A13: 0.7 | B13: 9 | C13: 8 | D13: 1 | E13: 2 | F13: =D13/(D13+108) -> 0.0091743119 | G13: =E13/(C13+E13) -> 0.2 | H13: =C13/(C13+D13) -> 0.88888889 | I13: =C13/(C13+E13) -> 0.8 | J13: =108/(108+D13) -> 0.99082569 | K13: =(I13+J13)/2 -> 0.89541284 | L13: 8 | M13: 8 | N13: 0 | O13: 2 | P13: =N13/(N13+108) -> 0 | Q13: =O13/(M13+O13) -> 0.2 | R13: =M13/(M13+N13) -> 1 | S13: =M13/(M13+O13) -> 0.8 | T13: =108/(108+N13) -> 1 | U13: =(S13+T13)/2 -> 0.9
A14: 0.8 | B14: 6 | C14: 6 | D14: 0 | E14: 4 | F14: =D14/(D14+108) -> 0 | G14: =E14/(C14+E14) -> 0.4 | H14: =C14/(C14+D14) -> 1 | I14: =C14/(C14+E14) -> 0.6 | J14: =108/(108+D14) -> 1 | K14: =(I14+J14)/2 -> 0.8 | L14: 6 | M14: 6 | N14: 0 | O14: 4 | P14: =N14/(N14+108) -> 0 | Q14: =O14/(M14+O14) -> 0.4 | R14: =M14/(M14+N14) -> 1 | S14: =M14/(M14+O14) -> 0.6 | T14: =108/(108+N14) -> 1 | U14: =(S14+T14)/2 -> 0.8
A15: 0.9 | B15: 3 | C15: 3 | D15: 0 | E15: 7 | F15: =D15/(D15+108) -> 0 | G15: =E15/(C15+E15) -> 0.7 | H15: =C15/(C15+D15) -> 1 | I15: =C15/(C15+E15) -> 0.3 | J15: =108/(108+D15) -> 1 | K15: =(I15+J15)/2 -> 0.65 | L15: 3 | M15: 3 | N15: 0 | O15: 7 | P15: =N15/(N15+108) -> 0 | Q15: =O15/(M15+O15) -> 0.7 | R15: =M15/(M15+N15) -> 1 | S15: =M15/(M15+O15) -> 0.3 | T15: =108/(108+N15) -> 1 | U15: =(S15+T15)/2 -> 0.65

Sheet HICEAS17_SCORES
A1: TP | B1: FP | C1: Filename | D1: event.id | E1: predicted | F1: X33 | G1: X577 | H1: original | I1: correct | K1: True Negatives = 486
A2: v | C2: 305 | D2: 1705416 | E2: X33 | F2: 0.9954 | G2: 0.0046 | H2: X33 | I2: TRUE | K2: 1706259 DW only. No valid EC Data, which is probably lowering the score. Update: 4/7/25 This is a mixed species encounter with AC258 and the ship is not at full speed. No not use in analysis.
A3: v | C3: 93 | D3: 1705109 | E3: X33 | F3: 0.9857 | G3: 0.0143 | H3: X33 | I3: TRUE
A4: v | C4: 236 | D4: 1706298 | E4: X33 | F4: 0.9301 | G4: 0.0699 | H4: X33 | I4: TRUE
A5: a | C5: 245 | D5: 1705307 | E5: X33 | F5: 0.9145 | G5: 0.0855 | H5: X277 | I5: FALSE | J5: AC
A6: v | C6: 65 | D6: 1706081 | E6: X33 | F6: 0.9045 | G6: 0.0955 | H6: X33 | I6: TRUE
A7: v | C7: 246 | D7: 1705308 | E7: X33 | F7: 0.904 | G7: 0.096 | H7: X33 | I7: TRUE
A8: v | C8: 92 | D8: 1705108 | E8: X33 | F8: 0.8837 | G8: 0.1163 | H8: X33 | I8: TRUE
A9: a | C9: 286 | D9: 1705385 | E9: X33 | F9: 0.8813 | G9: 0.1187 | H9: X77 | I9: FALSE | J9: AC
B10: a | C10: 234 | D10: 1706296 | E10: X33 | F10: 0.8738 | G10: 0.1262 | H10: X77 | I10: FALSE | J10: NO | K10: Not enough signals (<10). DW do look possible.
A11: v | C11: 72 | D11: 1706091 | E11: X33 | F11: 0.8715 | G11: 0.1285 | H11: X33 | I11: TRUE
A12: v | C12: 4 | D12: 1706007 | E12: X33 | F12: 0.8711 | G12: 0.1289 | H12: X33 | I12: TRUE
A13: v | C13: 233 | D13: 1705280 | E13: X33 | F13: 0.8693 | G13: 0.1307 | H13: X33 | I13: TRUE
A14: a | C14: 66 | D14: 1705075 | E14: X33 | F14: 0.8686 | G14: 0.1314 | H14: X77 | I14: FALSE | J14: AC
A15: v | C15: 230 | D15: 1705276 | E15: X33 | F15: 0.8639 | G15: 0.1361 | H15: X33 | I15: TRUE
A16: v | C16: 232 | D16: 1705279 | E16: X33 | F16: 0.8606 | G16: 0.1394 | H16: X33 | I16: TRUE
A17: v | C17: 15 | D17: 1705016 | E17: X33 | F17: 0.8536 | G17: 0.1464 | H17: X33 | I17: TRUE
A18: v | C18: 59 | D18: 1705067 | E18: X33 | F18: 0.8512 | G18: 0.1488 | H18: X33 | I18: TRUE
A19: a | C19: 175 | D19: 1705210 | E19: X33 | F19: 0.8477 | G19: 0.1523 | H19: X33 | I19: FALSE | J19: AC | K19: Pc before turn for Spotters
A20: a | C20: 237 | D20: 1705292 | E20: X33 | F20: 0.8434 | G20: 0.1566 | H20: X77 | I20: FALSE | J20: AC
B21: a | C21: 225 | D21: 1706279 | E21: X33 | F21: 0.8373 | G21: 0.1627 | H21: X77 | I21: FALSE | J21: NO | K21: Not enough signals (<5). DW do look possible.
A22: v | C22: 81 | D22: 1706101 | E22: X33 | F22: 0.8338 | G22: 0.1662 | H22: X33 | I22: TRUE
A23: v | C23: 227 | D23: 1706281 | E23: X33 | F23: 0.8304 | G23: 0.1696 | H23: X33 | I23: TRUE
A24: a | C24: 216 | D24: 1706269 | E24: X33 | F24: 0.8261 | G24: 0.1739 | H24: X77 | I24: FALSE | J24: AC
A25: v | C25: 233 | D25: 1706295 | E25: X33 | F25: 0.8256 | G25: 0.1744 | H25: X33 | I25: TRUE
A26: a | C26: 105 | D26: 1706127 | E26: X33 | F26: 0.8172 | G26: 0.1828 | H26: X77 | I26: FALSE | J26: AC
A27: a | C27: 183 | D27: 1706132 | E27: X33 | F27: 0.8098 | G27: 0.1902 | H27: X77 | I27: FALSE | J27: AC
A28: v | C28: 209 | D28: 1706256 | E28: X33 | F28: 0.8091 | G28: 0.1909 | H28: X33 | I28: TRUE
A29: v | C29: 265 | D29: 1706338 | E29: X33 | F29: 0.7947 | G29: 0.2053 | H29: X33 | I29: TRUE
A30: v | C30: 211 | D30: 1706258 | E30: X33 | F30: 0.7911 | G30: 0.2089 | H30: X33 | I30: TRUE
B31: a | C31: 258 | D31: 1705323 | E31: X33 | F31: 0.7742 | G31: 0.2258 | H31: X77 | I31: FALSE | J31: NO | K31: DW as possibly correct, but the EC has a Median Peak Freq of 65kHz
B32: a | C32: 186 | D32: 1705222 | E32: X33 | F32: 0.7603 | G32: 0.2397 | H32: X77 | I32: FALSE | J32: NO | K32: DW as possibly correct, but the EC has a Median Peak Freq of 26kHz
A33: v | C33: 179 | D33: 1705214 | E33: X33 | F33: 0.7564 | G33: 0.2436 | H33: X33 | I33: TRUE
B34: a | C34: 229 | D34: 1706286 | E34: X33 | F34: 0.7344 | G34: 0.2656 | H34: X77 | I34: FALSE | J34: NO | K34: Not enough signals (<5).
B35: a | C35: 153 | D35: 1705177 | E35: X33 | F35: 0.7338 | G35: 0.2662 | H35: X77 | I35: FALSE | J35: NO | K35: Not enough signals (<15).
B36: a | C36: 87 | D36: 1706107 | E36: X33 | F36: 0.7313 | G36: 0.2687 | H36: X77 | I36: FALSE | J36: NO | K36: Not enough signals (<5).
B37: a | C37: 73 | D37: 1705087 | E37: X33 | F37: 0.7295 | G37: 0.2705 | H37: X77 | I37: FALSE | J37: NO | K37: Not enough signals (<15).
B38: a | C38: 96 | D38: 1705113 | E38: X33 | F38: 0.7276 | G38: 0.2724 | H38: X77 | I38: FALSE | J38: NO | K38: Not enough signals (<15). DW do look possible.
B39: a | C39: 129 | D39: 1705152 | E39: X33 | F39: 0.7117 | G39: 0.2883 | H39: X77 | I39: FALSE | J39: NO | K39: Another type of blackfish. Maybe peps. YB checked it's acoustic
A40: a | C40: 52 | D40: 1706065 | E40: X33 | F40: 0.7045 | G40: 0.2955 | H40: X77 | I40: FALSE | J40: AC
...

Sheet HICEAS23_SCORES
A1: TP | B1: FP | C1: Filename | D1: event.id | E1: predicted | F1: X33 | G1: X577 | H1: original | I1: correct | K1: True Negatives = 337
A2: v | C2: 238 | D2: 2303309 | E2: X33 | F2: 0.9367 | G2: 0.0633 | H2: X33 | I2: TRUE
A3: a | C3: 47 | D3: 2303056 | E3: X33 | F3: 0.9256 | G3: 0.0744 | H3: X277 | I3: FALSE | J3: AC
A4: v | C4: 118 | D4: 2303155 | E4: X33 | F4: 0.912 | G4: 0.088 | H4: X33 | I4: TRUE
A5: a | C5: 278 | D5: 2303356 | E5: X33 | F5: 0.887 | G5: 0.113 | H5: X377 | I5: FALSE | J5: AC
B6: a | C6: 254 | D6: 2303331 | E6: X33 | F6: 0.8538 | G6: 0.1462 | H6: X277 | I6: FALSE | J6: NO | K6: Blackfish, but the DW in Pc range is actually the Sette noise. Issue with the rutter.
B7: a | C7: 231 | D7: 2303302 | E7: X33 | F7: 0.8324 | G7: 0.1676 | H7: X77 | I7: FALSE | J7: NO | K7: Not enough signals.
A8: v | C8: 134 | D8: 2303178 | E8: X33 | F8: 0.7983 | G8: 0.2017 | H8: X33 | I8: TRUE
A9: a | C9: 284 | D9: 2303362 | E9: X33 | F9: 0.7962 | G9: 0.2038 | H9: X77 | I9: FALSE | J9: AC
B10: a | C10: 8 | D10: 2401013 | E10: X33 | F10: 0.7921 | G10: 0.2079 | H10: X77 | I10: FALSE | J10: NO | K10: Not enough signals.
B11: a | C11: 255 | D11: 2303332 | E11: X33 | F11: 0.7709 | G11: 0.2291 | H11: X77 | I11: FALSE | J11: NO | K11: Not enough signals.
B12: a | C12: 19 | D12: 2303025 | E12: X33 | F12: 0.7634 | G12: 0.2366 | H12: X77 | I12: FALSE | J12: NO | K12: Not enough signals.
B13: a | C13: 173 | D13: 2303230 | E13: X33 | F13: 0.7404 | G13: 0.2596 | H13: X77 | I13: FALSE | J13: NO | K13: Not enough signals.
B14: a | C14: 146 | D14: 2303197 | E14: X33 | F14: 0.7397 | G14: 0.2603 | H14: X77 | I14: FALSE | J14: NO | K14: Not enough signals.
B15: a | C15: 57 | D15: 2401073 | E15: X33 | F15: 0.7375 | G15: 0.2625 | H15: X377 | I15: FALSE | J15: NO | K15: Not enough signals.
A16: v | C16: 100 | D16: 2303130 | E16: X33 | F16: 0.7368 | G16: 0.2632 | H16: X33 | I16: TRUE
B17: a | C17: 66 | D17: 2401083 | E17: X33 | F17: 0.7296 | G17: 0.2704 | H17: X77 | I17: FALSE | J17: NO | K17: Not enough signals.
B18: a | C18: 268 | D18: 2303346 | E18: X33 | F18: 0.7243 | G18: 0.2757 | H18: X177 | I18: FALSE | J18: NO | K18: EC > 22kHz
B19: v | C19: 180 | D19: 2303237 | E19: X33 | F19: 0.7136 | G19: 0.2864 | H19: X26 | I19: FALSE | J19: NO | K19: Visual confirm Fraser's dolphins
A20: v | C20: 260 | D20: 2303337 | E20: X33 | F20: 0.7114 | G20: 0.2886 | H20: X33 | I20: TRUE
B21: a | C21: 107 | D21: 2303141 | E21: X33 | F21: 0.7084 | G21: 0.2916 | H21: X77 | I21: FALSE | J21: NO | K21: DW not repeative in nature. Parts of signals might be lost due to detection distance reported at 10k for beam.
B22: a | C22: 242 | D22: 2303317 | E22: X33 | F22: 0.704 | G22: 0.296 | H22: X77 | I22: FALSE | J22: NO | K22: Not enough signals.
B23: a | C23: 214 | D23: 2303277 | E23: X33 | F23: 0.6711 | G23: 0.3289 | H23: X77 | I23: FALSE | J23: NO | K23: Not enough signals.
B24: a | C24: 63 | D24: 2303079 | E24: X33 | F24: 0.6596 | G24: 0.3404 | H24: X377 | I24: FALSE | J24: NO | K24: Not enough signals.
B25: a | C25: 8 | D25: 2303010 | E25: X33 | F25: 0.638 | G25: 0.362 | H25: X377 | I25: FALSE | J25: NO | K25: Not enough signals.
B26: a | C26: 150 | D26: 2303203 | E26: X33 | F26: 0.6233 | G26: 0.3767 | H26: X77 | I26: FALSE | J26: NO | K26: EC > 22kHz
A27: a | C27: 248 | D27: 2303324 | E27: X33 | F27: 0.6126 | G27: 0.3874 | H27: X377 | I27: FALSE | J27: AC
B28: a | C28: 38 | D28: 2303047 | E28: X33 | F28: 0.6122 | G28: 0.3878 | H28: X277 | I28: FALSE | J28: NO | K28: EC > 22kHz
B29: a | C29: 99 | D29: 2303129 | E29: X33 | F29: 0.6121 | G29: 0.3879 | H29: X46 | I29: FALSE | J29: NO | K29: Not enough signals.
B30: a | C30: 239 | D30: 2303313 | E30: X33 | F30: 0.6046 | G30: 0.3954 | H30: X377 | I30: FALSE | J30: NO | K30: EC > 22kHz - visual 77, unid
B31: a | C31: 221 | D31: 2303291 | E31: X33 | F31: 0.6045 | G31: 0.3955 | H31: X77 | I31: FALSE | J31: NO | K31: Not enough signals.
A32: a | C32: 82 | D32: 2401104 | E32: X33 | F32: 0.6015 | G32: 0.3985 | H32: X377 | I32: FALSE | J32: AC
B33: a | C33: 110 | D33: 2303144 | E33: X33 | F33: 0.5932 | G33: 0.4068 | H33: X77 | I33: FALSE | J33: NO | K33: EC > 22kHz
A34: a | C34: 212 | D34: 2303275 | E34: X33 | F34: 0.5902 | G34: 0.4098 | H34: X77 | I34: FALSE | J34: AC | K34: Don't use for localization project because ship was off effort chasing beaked whales.
B35: a | C35: 41 | D35: 2303050 | E35: X33 | F35: 0.583 | G35: 0.417 | H35: X277 | I35: FALSE | J35: NO | K35: EC > 22kHz
B36: a | C36: 31 | D36: 2401044 | E36: X33 | F36: 0.5798 | G36: 0.4202 | H36: X77 | I36: FALSE | J36: NO | K36: Not enough signals.
B37: a | C37: 252 | D37: 2303329 | E37: X33 | F37: 0.5716 | G37: 0.4284 | H37: X78 | I37: FALSE | J37: NO | K37: Not enough signals. - visual unid small whale
B38: a | C38: 26 | D38: 2303033 | E38: X33 | F38: 0.5714 | G38: 0.4286 | H38: X377 | I38: FALSE | J38: NO | K38: EC > 22kHz
A39: a | C39: 131 | D39: 2303172 | E39: X33 | F39: 0.5649 | G39: 0.4351 | H39: X377 | I39: FALSE | J39: AC
B40: v | C40: 200 | D40: 2303262 | E40: X33 | F40: 0.5575 | G40: 0.4425 | H40: X15 | I40: FALSE | J40: NO | K40: EC > 22kHz - visual Steno
...

Sheet SCOPE24_SCORES
A1: TP | B1: FP | C1: Filename | D1: event.id | E1: predicted | F1: X33 | G1: X577 | H1: original | I1: correct
A2: v | C2: 16 | D2: 2404021 | E2: X33 | F2: 0.9455 | G2: 0.0545 | H2: X33 | I2: TRUE
A3: v | C3: 65 | D3: 2404091 | E3: X33 | F3: 0.9194 | G3: 0.0806 | H3: X33 | I3: TRUE
A4: v | C4: 91 | D4: 2404128 | E4: X33 | F4: 0.9064 | G4: 0.0936 | H4: X33 | I4: TRUE
A5: a | C5: 13 | D5: 2404018 | E5: X33 | F5: 0.8893 | G5: 0.1107 | H5: X33 | I5: FALSE | J5: AC
A6: v | C6: 89 | D6: 2404126 | E6: X33 | F6: 0.8657 | G6: 0.1343 | H6: X33 | I6: TRUE
A7: a | C7: 50 | D7: 2404070 | E7: X33 | F7: 0.8143 | G7: 0.1857 | H7: X33 | I7: TRUE | J7: AC
A8: a | C8: 74 | D8: 2404105 | E8: X33 | F8: 0.7626 | G8: 0.2374 | H8: X33 | I8: TRUE | J8: AC
A9: a | C9: 87 | D9: 2404121 | E9: X33 | F9: 0.7374 | G9: 0.2626 | H9: X33 | I9: TRUE | J9: AC
B10: v | C10: 118 | D10: 2404160 | E10: X33 | F10: 0.7118 | G10: 0.2882 | H10: X15 | I10: FALSE | J10: NO | K10: No enough signals.
A11: a | C11: 38 | D11: 2404057 | E11: X33 | F11: 0.691 | G11: 0.309 | H11: X33 | I11: TRUE | J11: AC
B12: v | C12: 110 | D12: 2404149 | E12: X33 | F12: 0.5844 | G12: 0.4156 | H12: X15 | I12: FALSE | J12: NO | K12: Median peak frequency > 22kHz
A13: v | C13: 9 | D13: 2404013 | E13: X33 | F13: 0.5208 | G13: 0.4792 | H13: X33 | I13: TRUE | K13: Noise mixed into EC data. Most likely leading to a lower score.
B14: a | C14: 14 | D14: 2404019 | E14: X33 | F14: 0.5119 | G14: 0.4881 | H14: X77 | I14: FALSE | J14: NO | K14: Other type of blackfish. Slope of EC data is too high.
B15: v | C15: 112 | D15: 2404151 | E15: X33 | F15: 0.5079 | G15: 0.4921 | H15: X15 | I15: FALSE | J15: NO | K15: Median peak frequency > 22kHz
C16: 78 | D16: 2404111 | E16: X577 | F16: 0.4847 | G16: 0.5153 | H16: X77 | I16: FALSE
C17: 37 | D17: 2404056 | E17: X577 | F17: 0.4189 | G17: 0.5811 | H17: X177 | I17: FALSE
C18: 69 | D18: 2404095 | E18: X577 | F18: 0.3629 | G18: 0.6371 | H18: X377 | I18: FALSE
C19: 76 | D19: 2404107 | E19: X577 | F19: 0.2963 | G19: 0.7037 | H19: X36 | I19: FALSE
C20: 102 | D20: 2404141 | E20: X577 | F20: 0.2884 | G20: 0.7116 | H20: X37 | I20: FALSE
C21: 8 | D21: 2404012 | E21: X577 | F21: 0.2868 | G21: 0.7132 | H21: X377 | I21: FALSE
C22: 97 | D22: 2404136 | E22: X577 | F22: 0.2587 | G22: 0.7413 | H22: X77 | I22: FALSE
C23: 104 | D23: 2404143 | E23: X577 | F23: 0.2513 | G23: 0.7487 | H23: X277 | I23: FALSE
C24: 106 | D24: 2404145 | E24: X577 | F24: 0.2377 | G24: 0.7623 | H24: X15 | I24: FALSE
C25: 114 | D25: 2404154 | E25: X577 | F25: 0.2331 | G25: 0.7669 | H25: X15 | I25: FALSE
C26: 1 | D26: 2404001 | E26: X577 | F26: 0.2273 | G26: 0.7727 | H26: X15 | I26: FALSE
C27: 39 | D27: 2404058 | E27: X577 | F27: 0.2146 | G27: 0.7854 | H27: X31 | I27: FALSE
... C123: 56 | D123: 2404082 | E123: X577 | F123: 0.0171 | G123: 0.9829 | H123: X46 | I123: FALSE
